<?xml version="1.0" encoding="utf-8"?>
<!-- =================================================================================== -->
<!-- |    This document was autogenerated by xacro from DoubleArmV7A-TNK.urdf.xacro    | -->
<!-- |    EDITING THIS FILE BY HAND IS NOT RECOMMENDED                                 | -->
<!-- =================================================================================== -->
<robot name="DoubleArmV7-TNK">
  <!-- == footprint frame == -->
  <link name="base_footprint"/>
  <joint name="base_footprint_to_TFRAME" type="fixed">
    <origin xyz="0 0 0.520"/>
    <parent link="base_footprint"/>
    <child link="TFRAME"/>
  </joint>
  <!-- == Material == -->
  <material name="mframe_color">
    <color rgba="0.2 0.2 0.2 1"/>
  </material>
  <material name="block_color">
    <color rgba="1 0.85 0.33 1"/>
  </material>
  <material name="boom_color">
    <color rgba="1 0.85 0.33 1"/>
  </material>
  <material name="arm_color">
    <color rgba="1 0.85 0.33 1"/>
  </material>
  <material name="tohku_pitch_color">
    <color rgba="0.5 0.5 0.5 1"/>
  </material>
  <material name="tohku_roll_color">
    <color rgba="0.39 0.51 0.91 1"/>
  </material>
  <material name="tohku_tip_color">
    <color rgba="0.7 0.7 0.7 1"/>
  </material>
  <!-- Link -->
  <link name="MFRAME">
    <visual>
      <origin rpy="1.57079637 0 3.14159274"/>
      <material name="mframe_color"/>
      <geometry>
        <mesh filename="package://double_arm_tnk_description/meshes/middleframe.stl"/>
      </geometry>
    </visual>
    <collision>
      <origin rpy="1.57079637 0 3.14159274"/>
      <geometry>
        <mesh filename="package://double_arm_tnk_description/meshes/middleframe.stl"/>
      </geometry>
    </collision>
    <inertial>
      <mass value="455.45935E-3"/>
      <origin rpy="0 -0 0" xyz="7.35035370E-02 1.06590700E-01 1.61371410E-02"/>
      <inertia ixx="4.19870890E-4" ixy="1.70520040E-5" ixz="-6.24433200E-5" iyy="9.66620960E-4" iyz="-6.61440150E-6" izz="6.14020130E-4"/>
    </inertial>
  </link>
  <link name="BLOCK">
    <visual>
      <origin rpy="1.57079637 0 3.14159274"/>
      <material name="block_color"/>
      <geometry>
        <mesh filename="package://double_arm_tnk_description/meshes/swingbrkt.stl"/>
      </geometry>
    </visual>
    <collision>
      <origin rpy="1.57079637 0 3.14159274"/>
      <geometry>
        <mesh filename="package://double_arm_tnk_description/meshes/swingbrkt.stl"/>
      </geometry>
    </collision>
    <inertial>
      <mass value="27.099865985502E-3"/>
      <origin rpy="0 -0 0" xyz="-6.78385281318872e-002 1.77765761382185e-002 -6.67318029447292e-003"/>
      <inertia ixx="0.328996567191697e-5" ixy="5.52858323486756e-8" ixz="5.74693929208142e-8" iyy="0.160727640206049e-5" iyz="-1.33419251009407e-7" izz="0.319147626929996e-5"/>
    </inertial>
  </link>
  <link name="BOOM">
    <visual>
      <material name="boom_color"/>
      <geometry>
        <mesh filename="package://double_arm_tnk_description/meshes/cp_boom.stl"/>
      </geometry>
    </visual>
    <collision>
      <geometry>
        <mesh filename="package://double_arm_tnk_description/meshes/cp_boom.stl"/>
      </geometry>
    </collision>
    <inertial>
      <mass value="88.2695650987E-3"/>
      <origin rpy="0 -0 0" xyz="-0.831227871921433 0.142962825496583 0.0"/>
      <inertia ixx="1.48138597730672e-5" ixy="0.1902362002908e-5" ixz="1.05546586084014e-20" iyy="31.4435403431583e-5" iyz="-2.05305944696362e-22" izz="32.5752155940256e-5"/>
    </inertial>
  </link>
  <link name="ARM">
    <visual>
      <material name="arm_color"/>
      <geometry>
        <mesh filename="package://double_arm_tnk_description/meshes/cp_arm.stl"/>
      </geometry>
    </visual>
    <collision>
      <geometry>
        <mesh filename="package://double_arm_tnk_description/meshes/cp_arm.stl"/>
      </geometry>
    </collision>
    <inertial>
      <mass value="53.7797060658E-3"/>
      <origin rpy="0 -0 0" xyz="-0.133362844584537 0.0813367709948192 0.0"/>
      <inertia ixx="0.35420506763418e-5" ixy="-0.59676584437886e-5" ixz="1.78134245842626e-21" iyy="5.16579159038522e-5" iyz="6.97110293472855e-22" izz="5.39850890239257e-5"/>
    </inertial>
  </link>
  <link name="TOHKU_PITCH">
    <visual>
      <origin rpy="-1.57079637 -1.57079637 0"/>
      <material name="tohku_pitch_color"/>
      <geometry>
        <mesh filename="package://double_arm_tnk_description/meshes/tohku_hand_pitch.stl"/>
      </geometry>
    </visual>
    <collision>
      <origin rpy="-1.57079637 -1.57079637 0"/>
      <geometry>
        <mesh filename="package://double_arm_tnk_description/meshes/tohku_hand_pitch.stl"/>
      </geometry>
    </collision>
    <inertial>
      <mass value="2.1377092e-2"/>
      <origin rpy="0 -0 0" xyz="-1.2434069e-1 -6.6741207e-3 0.0000000e+00"/>
      <inertia ixx="2.4528689e-6" ixy="7.1716531e-8" ixz="0.0000000e+00" iyy="1.8144181e-6" iyz="0.0000000e+00" izz="2.1758796e-6"/>
    </inertial>
  </link>
  <link name="TOHKU_ROLL">
    <visual>
      <origin rpy="-1.57079637 -1.57079637 0"/>
      <material name="tohku_roll_color"/>
      <geometry>
        <mesh filename="package://double_arm_tnk_description/meshes/tohku_hand_roll.stl"/>
      </geometry>
    </visual>
    <collision>
      <origin rpy="-1.57079637 -1.57079637 0"/>
      <geometry>
        <mesh filename="package://double_arm_tnk_description/meshes/tohku_hand_roll.stl"/>
      </geometry>
    </collision>
    <inertial>
      <mass value="5.6820888e-2"/>
      <origin rpy="0 -0 0" xyz="-1.0832237e-1  0.0000000e+00  0.0000000e+00"/>
      <inertia ixx="7.8278692e-6" ixy="0.0000000e+00" ixz="0.0000000e+00" iyy="7.0832807e-6" iyz="0.0000000e+00" izz="1.1161951e-6"/>
    </inertial>
  </link>
  <link name="TOHKU_TIP_01">
    <visual>
      <origin rpy="-1.57079637 -1.57079637 0"/>
      <material name="tohku_tip_color"/>
      <geometry>
        <mesh filename="package://double_arm_tnk_description/meshes/tohku_hand_tip.stl"/>
      </geometry>
    </visual>
    <collision>
      <origin rpy="-1.57079637 -1.57079637 0"/>
      <geometry>
        <mesh filename="package://double_arm_tnk_description/meshes/tohku_hand_tip.stl"/>
      </geometry>
    </collision>
    <inertial>
      <mass value="9.3058947e-2"/>
      <origin rpy="0 -0 0" xyz="-1.9052236e-1  1.1160593e-1 -7.5632562e-04"/>
      <inertia ixx="3.0276157e-7" ixy="1.1688229e-7" ixz="1.2268932e-8" iyy="1.5080350e-7" iyz="-7.1011455e-9" izz="1.8011625e-6"/>
    </inertial>
  </link>
  <link name="TOHKU_TIP_02">
    <visual>
      <origin rpy="-1.57079637 -1.57079637 0"/>
      <material name="tohku_tip_color"/>
      <geometry>
        <mesh filename="package://double_arm_tnk_description/meshes/tohku_hand_tip.stl"/>
      </geometry>
    </visual>
    <collision>
      <origin rpy="-1.57079637 -1.57079637 0"/>
      <geometry>
        <mesh filename="package://double_arm_tnk_description/meshes/tohku_hand_tip.stl"/>
      </geometry>
    </collision>
    <inertial>
      <mass value="9.3058947e-2"/>
      <origin rpy="0 -0 0" xyz="-1.9052236e-1  1.1160593e-1 -7.5632562e-04"/>
      <inertia ixx="3.0276157e-7" ixy="1.1688229e-7" ixz="1.2268932e-8" iyy="1.5080350e-7" iyz="-7.1011455e-9" izz="1.8011625e-6"/>
    </inertial>
  </link>
  <!-- Joint -->
  <joint name="MFRAME" type="revolute">
    <origin rpy="0.0 -0.0 0.0" xyz="0.0 0.0 0.0"/>
    <axis xyz="0 0 1"/>
    <parent link="TFRAME"/>
    <child link="MFRAME"/>
    <limit effort="12000.0" lower="-11.9991386075" upper="11.9991386075" velocity="180.0"/>
  </joint>
  <joint name="BLOCK" type="revolute">
    <origin rpy="0.0 -0.0 0.0" xyz="0.845 -0.11 0.192"/>
    <axis xyz="0 0 1"/>
    <parent link="MFRAME"/>
    <child link="BLOCK"/>
    <limit effort="12000.0" lower="-0.837758040957" upper="1.21300383014" velocity="1146.0"/>
  </joint>
  <joint name="BOOM" type="revolute">
    <origin rpy="1.57079632679 8.65956056235e-17 3.14159265359" xyz="0.0700000000000004 1.5265566588595902e-16 0.20000000000000012"/>
    <axis xyz="0 0 1"/>
    <parent link="BLOCK"/>
    <child link="BOOM"/>
    <limit effort="15000.0" lower="-1.31074226825" upper="0.928515162061" velocity="1146.0"/>
  </joint>
  <joint name="ARM" type="revolute">
    <origin rpy="0.0 -0.0 0.0" xyz="-1.7599999999999993 5.551115123125783e-16 -9.71445146547012e-17"/>
    <axis xyz="0 0 1"/>
    <parent link="BOOM"/>
    <child link="ARM"/>
    <limit effort="12000.0" lower="0.535816080362" upper="2.65464579228" velocity="1146.0"/>
  </joint>
  <joint name="TOHKU_PITCH" type="revolute">
    <origin rpy="1.57079632679 -1.11022302463e-16 1.57079632679" xyz="-0.9649999999999999 1.6653345369377348e-16 -5.551115123125783e-17"/>
    <axis xyz="0 1 0"/>
    <parent link="ARM"/>
    <child link="TOHKU_PITCH"/>
    <limit effort="10000.0" lower="-0.588175957922" upper="1.57079632679" velocity="5730.0"/>
  </joint>
  <joint name="TOHKU_ROLL" type="revolute">
    <origin rpy="0.0 -0.0 0.0" xyz="9.992007221626409e-16 1.3183898417423734e-15 -0.22699999999999942"/>
    <axis xyz="0 0 1"/>
    <parent link="TOHKU_PITCH"/>
    <child link="TOHKU_ROLL"/>
    <limit effort="10000.0" lower="-3.14159265359" upper="3.14159265359" velocity="573.0"/>
  </joint>
  <joint name="TOHKU_TIP_01" type="revolute">
    <origin rpy="0.0 -0.0 0.0" xyz="9.992007221626409e-16 -7.077671781985373e-16 -0.3089999999999997"/>
    <axis xyz="0 1 0"/>
    <parent link="TOHKU_ROLL"/>
    <child link="TOHKU_TIP_01"/>
    <limit effort="10000.0" lower="-0.349065850399" upper="0.0" velocity="573.0"/>
  </joint>
  <joint name="TOHKU_TIP_02" type="revolute">
    <origin rpy="0.0 -0.0 3.14159265359" xyz="9.992007221626409e-16 -7.077671781985373e-16 -0.3089999999999997"/>
    <axis xyz="0 1 0"/>
    <parent link="TOHKU_ROLL"/>
    <child link="TOHKU_TIP_02"/>
    <limit effort="10000.0" lower="-0.349065850399" upper="0.0" velocity="573.0"/>
  </joint>
  <!-- Material -->
  <material name="uframe_color">
    <color rgba="1 0.85 0.33 1"/>
  </material>
  <material name="mnp_swing_color">
    <color rgba="1 0.85 0.33 1"/>
  </material>
  <material name="maniboom_color">
    <color rgba="1 0.85 0.33 1"/>
  </material>
  <material name="maniarm_color">
    <color rgba="1 0.85 0.33 1"/>
  </material>
  <material name="manielbow_color">
    <color rgba="0.89 0.89 1 1"/>
  </material>
  <material name="yawjoint_color">
    <color rgba="0.54 0.46 0.62 1"/>
  </material>
  <material name="handbase_color">
    <color rgba="0.4 0.4 0.4 0.9"/>
  </material>
  <material name="pushrod_color">
    <color rgba="0.87 0.87 0.91 1"/>
  </material>
  <material name="handslnk_i_color">
    <color rgba="0.4 0.4 0.4 1"/>
  </material>
  <material name="handslnk_o_color">
    <color rgba="0.4 0.4 0.4 1"/>
  </material>
  <material name="manifng_color">
    <color rgba="0.2 0.2 0.2 1"/>
  </material>
  <material name="handtip_color">
    <color rgba="0.9 0.9 0.9 1"/>
  </material>
  <material name="handlnk_color">
    <color rgba="0.87 0.7426 0.79 1"/>
  </material>
  <!-- Link -->
  <link name="UFRAME">
    <visual>
      <origin rpy="1.57079637 0 0"/>
      <material name="uframe_color"/>
      <geometry>
        <mesh filename="package://double_arm_tnk_description/meshes/frame_marge.stl"/>
      </geometry>
    </visual>
    <collision>
      <origin rpy="1.57079637 0 0"/>
      <geometry>
        <mesh filename="package://double_arm_tnk_description/meshes/frame_marge.stl"/>
      </geometry>
    </collision>
    <inertial>
      <mass value="535.84647E-3"/>
      <origin rpy="0 -0 0" xyz="8.14422630E-02 1.99598060E-01 2.71745980E-02"/>
      <inertia ixx="7.97084620E-4" ixy="-8.47185310E-5" ixz="1.11603580E-5" iyy="1.00038320E-3" iyz="5.51320690E-5" izz="6.17888570E-4"/>
    </inertial>
  </link>
  <link name="MNP_SWING">
    <visual>
      <origin rpy="1.57079637 0 3.14159274"/>
      <material name="mnp_swing_color"/>
      <geometry>
        <mesh filename="package://double_arm_tnk_description/meshes/mani_swgbrkt_v7.stl"/>
      </geometry>
    </visual>
    <collision>
      <origin rpy="1.57079637 0 3.14159274"/>
      <geometry>
        <mesh filename="package://double_arm_tnk_description/meshes/mani_swgbrkt_v7.stl"/>
      </geometry>
    </collision>
    <inertial>
      <mass value="1.3380749e-2"/>
      <origin rpy="0 -0 0" xyz="-6.7856551e-2 9.6877149e-3 0.0000000e+00"/>
      <inertia ixx="5.9129940e-7" ixy="-3.7243340e-8" ixz="0.0000000e+00" iyy="3.5238822e-7" iyz="0.0000000e+00" izz="7.3441120e-7"/>
    </inertial>
  </link>
  <link name="MANIBOOM">
    <visual>
      <material name="maniboom_color"/>
      <geometry>
        <mesh filename="package://double_arm_tnk_description/meshes/mani_boom_v7_2.stl"/>
      </geometry>
    </visual>
    <collision>
      <geometry>
        <mesh filename="package://double_arm_tnk_description/meshes/mani_boom_v7_2.stl"/>
      </geometry>
    </collision>
    <inertial>
      <mass value="36.291074E-3"/>
      <origin rpy="0 -0 0" xyz="-0.7599574 0.016703571 0.0"/>
      <inertia ixx="0.11028539e-5" ixy="0.04398908e-5" ixz="0.0" iyy="7.0046174e-5" iyz="0.0" izz="6.9737013e-5"/>
    </inertial>
  </link>
  <link name="MANIARM">
    <visual>
      <material name="maniarm_color"/>
      <geometry>
        <mesh filename="package://double_arm_tnk_description/meshes/mani_arm_v7_2.stl"/>
      </geometry>
    </visual>
    <collision>
      <geometry>
        <mesh filename="package://double_arm_tnk_description/meshes/mani_arm_v7_2.stl"/>
      </geometry>
    </collision>
    <inertial>
      <mass value="28.673428E-3"/>
      <origin rpy="0 -0 0" xyz="-0.18264981 0.17411666 0.0"/>
      <inertia ixx="0.19152986e-5" ixy="0.11443044e-5" ixz="0.0" iyy="0.79632756e-5" iyz="0.0" izz="0.81910511e-5"/>
    </inertial>
  </link>
  <link name="MANIELBOW">
    <visual>
      <origin rpy="-1.57079637 -1.57079637 0"/>
      <material name="manielbow_color"/>
      <geometry>
        <mesh filename="package://double_arm_tnk_description/meshes/mani_elbow_v7_marge.stl"/>
      </geometry>
    </visual>
    <collision>
      <origin rpy="-1.57079637 -1.57079637 0"/>
      <geometry>
        <mesh filename="package://double_arm_tnk_description/meshes/mani_elbow_v7_marge.stl"/>
      </geometry>
    </collision>
    <inertial>
      <mass value="2.3976610e-2"/>
      <origin rpy="0 -0 0" xyz="-4.7393726e-2 -3.4379664e-2 0.0000000e+00"/>
      <inertia ixx="1.5009182e-6" ixy="6.9121654e-7" ixz="0.0000000e+00" iyy="1.8822635e-6" iyz="0.0000000e+00" izz="2.3426912e-6"/>
    </inertial>
  </link>
  <link name="YAWJOINT">
    <visual>
      <origin rpy="0 -1.57079637 1.57079637"/>
      <material name="yawjoint_color"/>
      <geometry>
        <mesh filename="package://double_arm_tnk_description/meshes/mani_plan2_roll_v7.stl"/>
      </geometry>
    </visual>
    <collision>
      <origin rpy="0 -1.57079637 0"/>
      <geometry>
        <mesh filename="package://double_arm_tnk_description/meshes/mani_plan2_roll_v7.stl"/>
      </geometry>
    </collision>
    <inertial>
      <mass value="22.9404E-3"/>
      <origin rpy="0 -0 0" xyz="-0.169575 0 0.000436442"/>
      <inertia ixx="0.0917743e-5" ixy="0" ixz="-0.000933033e-5" iyy="0.193104e-5" iyz="0" izz="0.221433e-5"/>
    </inertial>
  </link>
  <link name="HANDBASE">
    <visual>
      <origin rpy="0 -1.57079637 0"/>
      <material name="handbase_color"/>
      <geometry>
        <mesh filename="package://double_arm_tnk_description/meshes/handbase_marge_v7.stl"/>
      </geometry>
    </visual>
    <collision>
      <origin rpy="0 -1.57079637 0"/>
      <geometry>
        <mesh filename="package://double_arm_tnk_description/meshes/handbase_marge_v7.stl"/>
      </geometry>
    </collision>
    <inertial>
      <mass value="4.08874E-3"/>
      <origin rpy="0 -0 0" xyz="-0.106437 0 0"/>
      <inertia ixx="0.00678026e-5" ixy="0" ixz="0" iyy="0.0266742e-5" iyz="0" izz="0.0241877e-5"/>
    </inertial>
  </link>
  <link name="PUSHROD">
    <visual>
      <origin rpy="0 -1.57079637 0"/>
      <material name="pushrod_color"/>
      <geometry>
        <mesh filename="package://double_arm_tnk_description/meshes/hand_rod_v7.stl"/>
      </geometry>
    </visual>
    <inertial>
      <mass value="0.887605E-3"/>
      <origin rpy="0 -0 0" xyz="0.0512686 0 0"/>
      <inertia ixx="0.000237569e-5" ixy="0" ixz="0" iyy="0.00159781e-5" iyz="0" izz="0.00159822e-5"/>
    </inertial>
  </link>
  <link name="HANDSLNK_I">
    <visual>
      <origin rpy="0 0 1.06864942243"/>
      <material name="handslnk_i_color"/>
      <geometry>
        <mesh filename="package://double_arm_tnk_description/meshes/hand_slink_inner_v7.stl"/>
      </geometry>
    </visual>
    <collision>
      <origin rpy="0 0 1.06864942243"/>
      <geometry>
        <mesh filename="package://double_arm_tnk_description/meshes/hand_slink_inner_v7.stl"/>
      </geometry>
    </collision>
    <inertial>
      <mass value="0.408083E-3"/>
      <origin rpy="0 -0 0" xyz="0.0530198 0.0 0.0"/>
      <inertia ixx="0.000186599e-5" ixy="0.0" ixz="0.0" iyy="0.000536909e-5" iyz="0.0" izz="0.000414755e-5"/>
    </inertial>
  </link>
  <link name="HANDSLNK_O">
    <visual>
      <origin rpy="0 0 -1.06864942243"/>
      <material name="handslnk_o_color"/>
      <geometry>
        <mesh filename="package://double_arm_tnk_description/meshes/hand_slink_outer_v7.stl"/>
      </geometry>
    </visual>
    <collision>
      <origin rpy="0 0 -1.06864942243"/>
      <geometry>
        <mesh filename="package://double_arm_tnk_description/meshes/hand_slink_outer_v7.stl"/>
      </geometry>
    </collision>
    <inertial>
      <mass value="0.408083E-3"/>
      <origin rpy="0 -0 0" xyz="0.053019776 0.0 0.0"/>
      <inertia ixx="0.000267073e-5" ixy="6.95893e-15" ixz="0.0" iyy="0.000617382e-5" iyz="0.0" izz="0.000414755e-5"/>
    </inertial>
  </link>
  <link name="MANIFNG_U">
    <visual>
      <origin rpy="0 0 -0.118127377683"/>
      <material name="manifng_color"/>
      <geometry>
        <mesh filename="package://double_arm_tnk_description/meshes/finger_base_v7.stl"/>
      </geometry>
    </visual>
    <collision>
      <origin rpy="0 0 -0.118127377683"/>
      <geometry>
        <mesh filename="package://double_arm_tnk_description/meshes/finger_base_v7.stl"/>
      </geometry>
    </collision>
    <inertial>
      <mass value="1.32092E-3"/>
      <origin rpy="0 -0 0" xyz="0.0778883 0.0150494 0.0"/>
      <inertia ixx="0.00159768e-5" ixy="0.000329267e-5" ixz="3.30872e-29" iyy="0.00595697e-5" iyz="1.03398e-30" izz="0.00524922e-5"/>
    </inertial>
  </link>
  <link name="HANDTIP_U">
    <visual>
      <origin rpy="0 0 0.118127377683"/>
      <material name="handtip_color"/>
      <geometry>
        <mesh filename="package://double_arm_tnk_description/meshes/hand_tip_asm_v7_marge.stl"/>
      </geometry>
    </visual>
    <collision>
      <origin rpy="0 0 0.118127377683"/>
      <geometry>
        <mesh filename="package://double_arm_tnk_description/meshes/hand_tip_asm_v7_marge.stl"/>
      </geometry>
    </collision>
    <inertial>
      <mass value="1.62187E-3"/>
      <origin rpy="0 -0 0" xyz="0.0581795 -0.0268036 0.0"/>
      <inertia ixx="0.00272616e-5" ixy="0.000478886e-5" ixz="-4.96308e-29" iyy="0.00389972e-5" iyz="1.03398e-29" izz="0.00225372e-5"/>
    </inertial>
  </link>
  <link name="HANDLNK_I">
    <visual>
      <origin rpy="0 0 0.118127377683" xyz="0 0 0.0065000000000000335"/>
      <material name="handlnk_color"/>
      <geometry>
        <mesh filename="package://double_arm_tnk_description/meshes/handlink_inner_v7.stl"/>
      </geometry>
    </visual>
    <collision>
      <origin rpy="0 0 0.118127377683" xyz="0 0 0.0065000000000000335"/>
      <geometry>
        <mesh filename="package://double_arm_tnk_description/meshes/handlink_inner_v7.stl"/>
      </geometry>
    </collision>
    <inertial>
      <mass value="0.732866E-3"/>
      <origin rpy="0 -0 0" xyz="0.0921655 -0.00204929 0.0"/>
      <inertia ixx="0.000257575e-5" ixy="5.00832e-11" ixz="0.0" iyy="0.00268959e-5" iyz="0.0" izz="0.00253442e-5"/>
    </inertial>
  </link>
  <link name="MANIFNG_L">
    <visual>
      <origin rpy="0 0 -0.118127377683"/>
      <material name="manifng_color"/>
      <geometry>
        <mesh filename="package://double_arm_tnk_description/meshes/finger_base_v7.stl"/>
      </geometry>
    </visual>
    <collision>
      <origin rpy="0 0 -0.118127377683"/>
      <geometry>
        <mesh filename="package://double_arm_tnk_description/meshes/finger_base_v7.stl"/>
      </geometry>
    </collision>
    <inertial>
      <mass value="1.32092E-3"/>
      <origin rpy="0 -0 0" xyz="0.0778883 0.0150494 0.0"/>
      <inertia ixx="0.00159768e-5" ixy="0.000329267e-5" ixz="0.0" iyy="0.00595697e-5" iyz="0.0" izz="0.00524922e-5"/>
    </inertial>
  </link>
  <link name="HANDTIP_L">
    <visual>
      <origin rpy="0 0 0.118127377683"/>
      <material name="handtip_color"/>
      <geometry>
        <mesh filename="package://double_arm_tnk_description/meshes/hand_tip_asm_v7_marge.stl"/>
      </geometry>
    </visual>
    <collision>
      <origin rpy="0 0 0.118127377683"/>
      <geometry>
        <mesh filename="package://double_arm_tnk_description/meshes/hand_tip_asm_v7_marge.stl"/>
      </geometry>
    </collision>
    <inertial>
      <mass value="1.62187E-3"/>
      <origin rpy="0 -0 0" xyz="0.0581795 -0.0268036 0.0"/>
      <inertia ixx="0.00272616e-5" ixy="0.000478886e-5" ixz="0.0" iyy="0.00389972e-5" iyz="0.0" izz="0.00225372e-5"/>
    </inertial>
  </link>
  <link name="HANDLNK_O">
    <visual>
      <origin rpy="0 0 0.118127377683" xyz="0 0 0.0065000000000000335"/>
      <material name="handlnk_color"/>
      <geometry>
        <mesh filename="package://double_arm_tnk_description/meshes/handlink_inner_v7.stl"/>
      </geometry>
    </visual>
    <collision>
      <origin rpy="0 0 0.118127377683" xyz="0 0 0.0065000000000000335"/>
      <geometry>
        <mesh filename="package://double_arm_tnk_description/meshes/handlink_inner_v7.stl"/>
      </geometry>
    </collision>
    <inertial>
      <mass value="0.871915E-3"/>
      <origin rpy="0 -0 0" xyz="0.0928285 -0.00312308 1.58819e-22"/>
      <inertia ixx="0.000559832e-5" ixy="-1.99551e-10" ixz="-1.65436e-29" iyy="0.00316998e-5" iyz="3.61892e-30" izz="0.00272764e-5"/>
    </inertial>
  </link>
  <!-- Joint -->
  <joint name="UFRAME" type="revolute">
    <origin rpy="0.0 -0.0 3.14159265359" xyz="0.0 0.0 0.3"/>
    <axis xyz="0 0 1"/>
    <parent link="TFRAME"/>
    <child link="UFRAME"/>
    <limit effort="12000.0" lower="-11.9991386075" upper="11.9991386075" velocity="573.0"/>
  </joint>
  <joint name="MNP_SWING" type="revolute">
    <origin rpy="0.0 -0.0 0.0" xyz="0.5595 -0.13 0.11800000000000005"/>
    <axis xyz="0 0 1"/>
    <parent link="UFRAME"/>
    <child link="MNP_SWING"/>
    <limit effort="12000.0" lower="-1.0471975512" upper="1.0471975512" velocity="1146.0"/>
  </joint>
  <joint name="MANIBOOM" type="revolute">
    <origin rpy="-1.57079632679 1.57079632679 0.0" xyz="0.07000000000000028 1.942890293094024e-16 0.1400000000000003"/>
    <axis xyz="0 0 1"/>
    <parent link="MNP_SWING"/>
    <child link="MANIBOOM"/>
    <limit effort="15000.0" lower="0.0" upper="2.00712863979" velocity="573.0"/>
  </joint>
  <joint name="MANIARM" type="revolute">
    <origin rpy="0.0 -0.0 3.14159265359" xyz="-1.4799999999999995 0.0800000000000003 -4.718447854656915e-16"/>
    <axis xyz="0 0 1"/>
    <parent link="MANIBOOM"/>
    <child link="MANIARM"/>
    <limit effort="12000.0" lower="-1.91986217719" upper="0.0" velocity="573.0"/>
  </joint>
  <joint name="MANIELBOW" type="revolute">
    <origin rpy="1.57079632679 1.16573417586e-15 1.57079632679" xyz="-0.5499999999999989 0.27000000000000035 1.942890293094024e-16"/>
    <axis xyz="0 1 0"/>
    <parent link="MANIARM"/>
    <child link="MANIELBOW"/>
    <limit effort="10000.0" lower="-1.57079632679" upper="0.349065850399" velocity="573.0"/>
  </joint>
  <joint name="YAWJOINT" type="revolute">
    <origin rpy="0.0 -0.0 0.0" xyz="-4.440892098500626e-16 5.273559366969494e-16 -0.2300000000000002"/>
    <axis xyz="1 0 0"/>
    <parent link="MANIELBOW"/>
    <child link="YAWJOINT"/>
    <limit effort="10000.0" lower="-0.881042206407" upper="0.881042206407" velocity="573.0"/>
  </joint>
  <joint name="HANDBASE" type="revolute">
    <origin rpy="0.0 -0.0 0.0" xyz="-4.440892098500626e-16 -2.7755575615628914e-17 -0.40529999999999977"/>
    <axis xyz="0 0 -1"/>
    <parent link="YAWJOINT"/>
    <child link="HANDBASE"/>
    <limit effort="8000.0" lower="-4.71238898038" upper="4.71238898038" velocity="573.0"/>
  </joint>
  <joint name="PUSHROD" type="prismatic">
    <origin rpy="0.0 -0.0 0.0" xyz="-1.1102230246251565e-16 -2.7755575615628914e-17 -0.0917"/>
    <axis xyz="0 0 -1"/>
    <parent link="HANDBASE"/>
    <child link="PUSHROD"/>
    <limit effort="8000.0" lower="-0.000884881930761" upper="0.0" velocity="573.0"/>
  </joint>
  <joint name="HANDSLNK_I" type="revolute">
    <origin rpy="-1.57079632679 0.502146933762 3.14159265359" xyz="1.1102230246251565e-16 3.885780586188048e-16 1.1102230246251565e-16"/>
    <axis xyz="0 0 1"/>
    <parent link="PUSHROD"/>
    <child link="HANDSLNK_I"/>
    <limit effort="100.0" lower="-3.00022098418" upper="3.00022098418" velocity="573.0"/>
  </joint>
  <joint name="HANDSLNK_O" type="revolute">
    <origin rpy="1.57079632679 0.502146933762 1.89987128067e-16" xyz="1.1102230246251565e-16 3.885780586188048e-16 1.1102230246251565e-16"/>
    <axis xyz="0 0 1"/>
    <parent link="PUSHROD"/>
    <child link="HANDSLNK_O"/>
    <limit effort="100.0" lower="-3.00022098418" upper="3.00022098418" velocity="573.0"/>
  </joint>
  <joint name="MANIFNG_U" type="revolute">
    <origin rpy="1.57079632679 1.45266895236 4.23918814852e-15" xyz="0.029999999999999916 -2.7755575615628914e-17 -0.1399999999999999"/>
    <axis xyz="0 0 1"/>
    <parent link="HANDBASE"/>
    <child link="MANIFNG_U"/>
    <limit effort="100.0" lower="-3.00022098418" upper="3.00022098418" velocity="573.0"/>
  </joint>
  <joint name="HANDTIP_U" type="revolute">
    <origin rpy="-3.54187949632e-16 -1.17224040023e-16 -0.118127374433" xyz="0.1710000000000006 -2.220446049250313e-16 -3.885780586188048e-16"/>
    <axis xyz="0 0 1"/>
    <parent link="MANIFNG_U"/>
    <child link="HANDTIP_U"/>
    <limit effort="100.0" lower="-3.00022098418" upper="3.00022098418" velocity="573.0"/>
  </joint>
  <joint name="HANDLNK_I" type="revolute">
    <origin rpy="1.57079632679 1.45266895236 4.23918814852e-15" xyz="-1.1102230246251565e-16 0.006499999999999978 -0.15499999999999992"/>
    <axis xyz="0 0 1"/>
    <parent link="HANDBASE"/>
    <child link="HANDLNK_I"/>
    <limit effort="100.0" lower="-3.00022098418" upper="3.00022098418" velocity="573.0"/>
  </joint>
  <joint name="MANIFNG_L" type="revolute">
    <origin rpy="1.57079632679 1.45266922743 3.14159265359" xyz="-0.030000000000000027 0.0 -0.1399999999999999"/>
    <axis xyz="0 0 1"/>
    <parent link="HANDBASE"/>
    <child link="MANIFNG_L"/>
    <limit effort="100.0" lower="-3.00022098418" upper="3.00022098418" velocity="573.0"/>
  </joint>
  <joint name="HANDTIP_L" type="revolute">
    <origin rpy="-9.18211105227e-19 9.17549819597e-17 -0.118127374433" xyz="0.17099999999999982 4.440892098500626e-16 3.0531133177191805e-16"/>
    <axis xyz="0 0 1"/>
    <parent link="MANIFNG_L"/>
    <child link="HANDTIP_L"/>
    <limit effort="100.0" lower="-3.00022098418" upper="3.00022098418" velocity="573.0"/>
  </joint>
  <joint name="HANDLNK_O" type="revolute">
    <origin rpy="1.57079632679 1.45266922743 3.14159265359" xyz="-1.1102230246251565e-16 -0.0065000000000000335 -0.15499999999999992"/>
    <axis xyz="0 0 1"/>
    <parent link="HANDBASE"/>
    <child link="HANDLNK_O"/>
    <limit effort="100.0" lower="-3.00022098418" upper="3.00022098418" velocity="573.0"/>
  </joint>
  <!-- == Material == -->
  <material name="wheel_color">
    <color rgba="0.3 0.3 0.3 1"/>
  </material>
  <material name="wheel_guard_color">
    <color rgba="0.3 0.3 0.3 0.8"/>
  </material>
  <material name="tframe_color">
    <color rgba="0.3 0.3 0.3 1"/>
  </material>
  <!-- Link -->
  <link name="WHEEL_L0">
    <visual>
      <origin rpy="-1.57079637 0 0"/>
      <material name="wheel_color"/>
      <geometry>
        <cylinder length="0.25" radius="0.2"/>
      </geometry>
    </visual>
    <inertial>
      <mass value="13.25E-3"/>
      <origin rpy="0 -0 0" xyz="0.0 0.0 0.0"/>
      <inertia ixx="0.2015E-5" ixy="0.0" ixz="0.0" iyy="0.265E-5" iyz="0.0" izz="0.2015E-5"/>
    </inertial>
  </link>
  <link name="WHEEL_L1">
    <visual>
      <origin rpy="-1.57079637 0 0"/>
      <material name="wheel_color"/>
      <geometry>
        <cylinder length="0.25" radius="0.2"/>
      </geometry>
    </visual>
    <inertial>
      <mass value="13.25E-3"/>
      <origin rpy="0 -0 0" xyz="0.0 0.0 0.0"/>
      <inertia ixx="0.2015E-5" ixy="0.0" ixz="0.0" iyy="0.265E-5" iyz="0.0" izz="0.2015E-5"/>
    </inertial>
  </link>
  <link name="WHEEL_L2">
    <visual>
      <origin rpy="-1.57079637 0 0"/>
      <material name="wheel_color"/>
      <geometry>
        <cylinder length="0.25" radius="0.2"/>
      </geometry>
    </visual>
    <inertial>
      <mass value="13.25E-3"/>
      <origin rpy="0 -0 0" xyz="0.0 0.0 0.0"/>
      <inertia ixx="0.2015E-5" ixy="0.0" ixz="0.0" iyy="0.265E-5" iyz="0.0" izz="0.2015E-5"/>
    </inertial>
  </link>
  <link name="WHEEL_L3">
    <visual>
      <origin rpy="-1.57079637 0 0"/>
      <material name="wheel_color"/>
      <geometry>
        <cylinder length="0.25" radius="0.2"/>
      </geometry>
    </visual>
    <inertial>
      <mass value="13.25E-3"/>
      <origin rpy="0 -0 0" xyz="0.0 0.0 0.0"/>
      <inertia ixx="0.2015E-5" ixy="0.0" ixz="0.0" iyy="0.265E-5" iyz="0.0" izz="0.2015E-5"/>
    </inertial>
  </link>
  <link name="WHEEL_R0">
    <visual>
      <origin rpy="-1.57079637 0 0"/>
      <material name="wheel_color"/>
      <geometry>
        <cylinder length="0.25" radius="0.2"/>
      </geometry>
    </visual>
    <inertial>
      <mass value="13.25E-3"/>
      <origin rpy="0 -0 0" xyz="0.0 0.0 0.0"/>
      <inertia ixx="0.2015E-5" ixy="0.0" ixz="0.0" iyy="0.265E-5" iyz="0.0" izz="0.2015E-5"/>
    </inertial>
  </link>
  <link name="WHEEL_R1">
    <visual>
      <origin rpy="-1.57079637 0 0"/>
      <material name="wheel_color"/>
      <geometry>
        <cylinder length="0.25" radius="0.2"/>
      </geometry>
    </visual>
    <inertial>
      <mass value="13.25E-3"/>
      <origin rpy="0 -0 0" xyz="0.0 0.0 0.0"/>
      <inertia ixx="0.2015E-5" ixy="0.0" ixz="0.0" iyy="0.265E-5" iyz="0.0" izz="0.2015E-5"/>
    </inertial>
  </link>
  <link name="WHEEL_R2">
    <visual>
      <origin rpy="-1.57079637 0 0"/>
      <material name="wheel_color"/>
      <geometry>
        <cylinder length="0.25" radius="0.2"/>
      </geometry>
    </visual>
    <inertial>
      <mass value="13.25E-3"/>
      <origin rpy="0 -0 0" xyz="0.0 0.0 0.0"/>
      <inertia ixx="0.2015E-5" ixy="0.0" ixz="0.0" iyy="0.265E-5" iyz="0.0" izz="0.2015E-5"/>
    </inertial>
  </link>
  <link name="WHEEL_R3">
    <visual>
      <origin rpy="-1.57079637 0 0"/>
      <material name="wheel_color"/>
      <geometry>
        <cylinder length="0.25" radius="0.2"/>
      </geometry>
    </visual>
    <inertial>
      <mass value="13.25E-3"/>
      <origin rpy="0 -0 0" xyz="0.0 0.0 0.0"/>
      <inertia ixx="0.2015E-5" ixy="0.0" ixz="0.0" iyy="0.265E-5" iyz="0.0" izz="0.2015E-5"/>
    </inertial>
  </link>
  <link name="WIRE_GUARD_L">
    <visual>
      <origin rpy="1.57079637 0 0" xyz="0.72 -0.01 0.0255"/>
      <material name="wheel_guard_color"/>
      <geometry>
        <mesh filename="package://double_arm_tnk_description/meshes/tframe.stl"/>
      </geometry>
    </visual>
    <collision>
      <origin rpy="1.57079637 0 0" xyz="0.72 -0.01 0.0255"/>
      <geometry>
        <mesh filename="package://double_arm_tnk_description/meshes/tframe.stl"/>
      </geometry>
    </collision>
    <inertial>
      <mass value="0.1E-3"/>
      <origin rpy="0 -0 0" xyz="0.0 0.0 0.0"/>
      <inertia ixx="0.001E-5" ixy="0.0" ixz="0.0" iyy="0.001E-5" iyz="0.0" izz="0.001E-5"/>
    </inertial>
  </link>
  <link name="WIRE_GUARD_R">
    <visual>
      <origin rpy="1.57079637 0 0" xyz="0.72 0.01 0.0255"/>
      <material name="wheel_guard_color"/>
      <geometry>
        <mesh filename="package://double_arm_tnk_description/meshes/tframe.stl"/>
      </geometry>
    </visual>
    <collision>
      <origin rpy="1.57079637 0 0" xyz="0.72 0.01 0.0255"/>
      <geometry>
        <mesh filename="package://double_arm_tnk_description/meshes/tframe.stl"/>
      </geometry>
    </collision>
    <inertial>
      <mass value="0.1E-3"/>
      <origin rpy="0 -0 0" xyz="0.0 0.0 0.0"/>
      <inertia ixx="0.001E-5" ixy="0.0" ixz="0.0" iyy="0.001E-5" iyz="0.0" izz="0.001E-5"/>
    </inertial>
  </link>
  <link name="TFRAME">
    <visual>
      <origin rpy="1.57079637 0 0"/>
      <material name="tframe_color"/>
      <geometry>
        <mesh filename="package://double_arm_tnk_description/meshes/frame1.stl"/>
      </geometry>
    </visual>
    <collision>
      <origin rpy="1.57079637 0 0"/>
      <geometry>
        <mesh filename="package://double_arm_tnk_description/meshes/frame1.stl"/>
      </geometry>
    </collision>
    <inertial>
      <mass value="445E-3"/>
      <origin rpy="0 -0 0" xyz="2.61167950E-02 -2.48536360E-01 7.38255770E-05"/>
      <inertia ixx="1.17125210E-3" ixy="9.30859190E-6" ixz="7.71323470E-8" iyy="2.13308730E-3" iyz="-4.07759970E-8" izz="1.08880120E-3"/>
    </inertial>
  </link>
  <!-- Joint -->
  <joint name="WHEEL_L0" type="continuous">
    <origin rpy="0.0 -0.0 0.0" xyz="0.74 0.6 -0.295"/>
    <axis xyz="0 1 0"/>
    <parent link="TFRAME"/>
    <child link="WHEEL_L0"/>
  </joint>
  <joint name="WHEEL_L1" type="continuous">
    <origin rpy="0.0 -0.0 0.0" xyz="0.26 0.6 -0.295"/>
    <axis xyz="0 1 0"/>
    <parent link="TFRAME"/>
    <child link="WHEEL_L1"/>
  </joint>
  <joint name="WHEEL_L2" type="continuous">
    <origin rpy="0.0 -0.0 0.0" xyz="-0.22 0.6 -0.295"/>
    <axis xyz="0 1 0"/>
    <parent link="TFRAME"/>
    <child link="WHEEL_L2"/>
  </joint>
  <joint name="WHEEL_L3" type="continuous">
    <origin rpy="0.0 -0.0 0.0" xyz="-0.7 0.6 -0.295"/>
    <axis xyz="0 1 0"/>
    <parent link="TFRAME"/>
    <child link="WHEEL_L3"/>
  </joint>
  <joint name="WHEEL_R0" type="continuous">
    <origin rpy="0.0 -0.0 0.0" xyz="0.74 -0.6 -0.295"/>
    <axis xyz="0 1 0"/>
    <parent link="TFRAME"/>
    <child link="WHEEL_R0"/>
  </joint>
  <joint name="WHEEL_R1" type="continuous">
    <origin rpy="0.0 -0.0 0.0" xyz="0.26 -0.6 -0.295"/>
    <axis xyz="0 1 0"/>
    <parent link="TFRAME"/>
    <child link="WHEEL_R1"/>
  </joint>
  <joint name="WHEEL_R2" type="continuous">
    <origin rpy="0.0 -0.0 0.0" xyz="-0.22 -0.6 -0.295"/>
    <axis xyz="0 1 0"/>
    <parent link="TFRAME"/>
    <child link="WHEEL_R2"/>
  </joint>
  <joint name="WHEEL_R3" type="continuous">
    <origin rpy="0.0 -0.0 0.0" xyz="-0.7 -0.6 -0.295"/>
    <axis xyz="0 1 0"/>
    <parent link="TFRAME"/>
    <child link="WHEEL_R3"/>
  </joint>
  <joint name="WIRE_GUARD_L" type="fixed">
    <origin rpy="0.0 -0.0 0.0" xyz="0.02 0.61 -0.32"/>
    <parent link="TFRAME"/>
    <child link="WIRE_GUARD_L"/>
  </joint>
  <joint name="WIRE_GUARD_R" type="fixed">
    <origin rpy="0.0 -0.0 0.0" xyz="0.02 -0.61 -0.32"/>
    <parent link="TFRAME"/>
    <child link="WIRE_GUARD_R"/>
  </joint>
  <!-- == Sensor == -->
  <!-- <xacro:include filename="$(find double_arm_tnk_description)/urdf/SENSOR.urdf.xacro"/> -->
</robot>

