<?xml version="1.0"?>
<robot xmlns:xacro="http://ros.org/wiki/xacro">

  <!-- Material -->
  <material name="uframe_color">
    <color rgba="1 0.85 0.33 1"/>
  </material>
  <material name="mnp_swing_color">
    <color rgba="1 0.85 0.33 1"/>
  </material>
  <material name="maniboom_color">
    <color rgba="1 0.85 0.33 1"/>
  </material>
  <material name="maniarm_color">
    <color rgba="1 0.85 0.33 1"/>
  </material>
  <material name="manielbow_color">
    <color rgba="0.89 0.89 1 1"/>
  </material>
  <material name="yawjoint_color">
    <color rgba="0.54 0.46 0.62 1"/>
  </material>
  <material name="handbase_color">
    <color rgba="0.4 0.4 0.4 0.9"/>
  </material>
  <material name="pushrod_color">
    <color rgba="0.87 0.87 0.91 1"/>
  </material>
  <material name="handslnk_i_color">
    <color rgba="0.4 0.4 0.4 1"/>
  </material>
  <material name="handslnk_o_color">
    <color rgba="0.4 0.4 0.4 1"/>
  </material>
  <material name="manifng_color">
    <color rgba="0.2 0.2 0.2 1"/>
  </material>
  <material name="handtip_color">
    <color rgba="0.9 0.9 0.9 1"/>
  </material>
  <material name="handlnk_color">
    <color rgba="0.87 0.7426 0.79 1"/>
  </material>

  
  <!-- Link -->
  <link name="UFRAME">
    <visual>
      <origin rpy="${M_PI/2} 0 0"/>
      <material name="uframe_color"/>
      <geometry>
        <mesh filename="package://double_arm_tnk_description/meshes/frame_marge.stl"/>
      </geometry>
    </visual>
    <collision>
      <origin rpy="${M_PI/2} 0 0"/>
      <geometry>
        <mesh filename="package://double_arm_tnk_description/meshes/frame_marge.stl"/>
      </geometry>      
    </collision>
    <inertial>
      <mass value="535.84647" />
      <origin xyz="8.14422630E-02 1.99598060E-01 2.71745980E-02" rpy="0 -0 0" />
      <inertia ixx="7.97084620E+01" ixy="-8.47185310E+00" ixz="1.11603580E+00" iyy="1.00038320E+02" iyz="5.51320690E+00" izz="6.17888570E+01" />
    </inertial>
  </link>

  <link name="MNP_SWING">
    <visual>
      <origin rpy="${M_PI/2} 0 ${M_PI}"/>
      <material name="mnp_swing_color"/>
      <geometry>
        <mesh filename="package://double_arm_tnk_description/meshes/mani_swgbrkt_v7.stl"/>
      </geometry>
    </visual>
    <collision>
      <origin rpy="${M_PI/2} 0 ${M_PI}"/>
      <geometry>
        <mesh filename="package://double_arm_tnk_description/meshes/mani_swgbrkt_v7.stl"/>
      </geometry>      
    </collision>
    <inertial>
      <mass value="1.3380749e-2" />
      <origin xyz="-6.7856551e-2 9.6877149e-3 0.0000000e+00" rpy="0 -0 0" />
      <inertia ixx="5.9129940e-7" ixy="-3.7243340e-8" ixz="0.0000000e+00" iyy="3.5238822e-7" iyz="0.0000000e+00" izz="7.3441120e-7" />
    </inertial>
  </link>

  <link name="MANIBOOM">
    <visual>
      <material name="maniboom_color"/>
      <geometry>
        <mesh filename="package://double_arm_tnk_description/meshes/mani_boom_v7_2.stl"/>
      </geometry>
    </visual>
    <collision>
      <geometry>
        <mesh filename="package://double_arm_tnk_description/meshes/mani_boom_v7_2.stl"/>
      </geometry>      
    </collision>
    <inertial>
      <mass value="36.291074E-3" />
      <origin xyz="-0.7599574 0.016703571 0.0" rpy="0 -0 0" />
      <inertia ixx="0.11028539e-5" ixy="0.04398908e-5" ixz="0.0" iyy="7.0046174e-5" iyz="0.0" izz="6.9737013e-5" />
    </inertial>
  </link>

  <link name="MANIARM">
    <visual>
      <material name="maniarm_color"/>
      <geometry>
        <mesh filename="package://double_arm_tnk_description/meshes/mani_arm_v7_2.stl"/>
      </geometry>
    </visual>
    <collision>
      <geometry>
        <mesh filename="package://double_arm_tnk_description/meshes/mani_arm_v7_2.stl"/>
      </geometry>      
    </collision>
    <inertial>
      <mass value="28.673428E-3" />
      <origin xyz="-0.18264981 0.17411666 0.0" rpy="0 -0 0" />
      <inertia ixx="0.19152986e-5" ixy="0.11443044e-5" ixz="0.0" iyy="0.79632756e-5" iyz="0.0" izz="0.81910511e-5" />
    </inertial>
  </link>

  <link name="MANIELBOW">
    <visual>
      <origin rpy="${-M_PI/2} ${-M_PI/2} 0"/>
      <material name="manielbow_color"/>
      <geometry>
        <mesh filename="package://double_arm_tnk_description/meshes/mani_elbow_v7_marge.stl"/>
      </geometry>
    </visual>
    <collision>
      <origin rpy="${-M_PI/2} ${-M_PI/2} 0"/>
      <geometry>
        <mesh filename="package://double_arm_tnk_description/meshes/mani_elbow_v7_marge.stl"/>
      </geometry>      
    </collision>
    <inertial>
      <mass value="2.3976610e-2" />
      <origin xyz="-4.7393726e-2 -3.4379664e-2 0.0000000e+00" rpy="0 -0 0" />
      <inertia ixx="1.5009182e-6" ixy="6.9121654e-7" ixz="0.0000000e+00" iyy="1.8822635e-6" iyz="0.0000000e+00" izz="2.3426912e-6" />
    </inertial>
  </link>

  <link name="YAWJOINT">
    <visual>
      <origin rpy="0 ${-M_PI/2} ${M_PI/2}"/>
      <material name="yawjoint_color"/>
      <geometry>
        <mesh filename="package://double_arm_tnk_description/meshes/mani_plan2_roll_v7.stl"/>
      </geometry>
    </visual>
    <collision>
      <origin rpy="0 ${-M_PI/2} 0"/>
      <geometry>
        <mesh filename="package://double_arm_tnk_description/meshes/mani_plan2_roll_v7.stl"/>
      </geometry>      
    </collision>
    <inertial>
      <mass value="22.9404E-3" />
      <origin xyz="-0.169575 0 0.000436442" rpy="0 -0 0" />
      <inertia ixx="0.0917743e-5" ixy="0" ixz="-0.000933033e-5" iyy="0.193104e-5" iyz="0" izz="0.221433e-5" />
    </inertial>
  </link>

  <link name="HANDBASE">
    <visual>
      <origin rpy="0 ${-M_PI/2} 0"/>
      <material name="handbase_color"/>
      <geometry>
        <mesh filename="package://double_arm_tnk_description/meshes/handbase_marge_v7.stl"/>
      </geometry>
    </visual>
    <collision>
      <origin rpy="0 ${-M_PI/2} 0"/>
      <geometry>
        <mesh filename="package://double_arm_tnk_description/meshes/handbase_marge_v7.stl"/>
      </geometry>      
    </collision>
    <inertial>
      <mass value="4.08874E-3" />
      <origin xyz="-0.106437 0 0" rpy="0 -0 0" />
      <inertia ixx="0.00678026e-5" ixy="0" ixz="0" iyy="0.0266742e-5" iyz="0" izz="0.0241877e-5" />
    </inertial>
  </link>

  <link name="PUSHROD">
    <visual>
      <origin rpy="0 ${-M_PI/2} 0"/>
      <material name="pushrod_color"/>
      <geometry>
        <mesh filename="package://double_arm_tnk_description/meshes/hand_rod_v7.stl"/>
      </geometry>
    </visual>
    <inertial>
      <mass value="0.887605E-3" />
      <origin xyz="0.0512686 0 0" rpy="0 -0 0" />
      <inertia ixx="0.000237569e-5" ixy="0" ixz="0" iyy="0.00159781e-5" iyz="0" izz="0.00159822e-5" />
    </inertial>
  </link>

  <link name="HANDSLNK_I">
    <visual>
      <origin rpy="0 0 ${61.2291*M_PI/180}"/>
      <material name="handslnk_i_color"/>
      <geometry>
        <mesh filename="package://double_arm_tnk_description/meshes/hand_slink_inner_v7.stl"/>
      </geometry>
    </visual>
    <collision>
      <origin rpy="0 0 ${61.2291*M_PI/180}"/>
      <geometry>
        <mesh filename="package://double_arm_tnk_description/meshes/hand_slink_inner_v7.stl"/>
      </geometry>      
    </collision>
    <inertial>
      <mass value="0.408083E-3" />
      <origin xyz="0.0530198 0.0 0.0" rpy="0 -0 0" />
      <inertia ixx="0.000186599e-5" ixy="0.0" ixz="0.0" iyy="0.000536909e-5" iyz="0.0" izz="0.000414755e-5" />
    </inertial>
  </link>

  <link name="HANDSLNK_O">
    <visual>
      <origin rpy="0 0 ${-61.2291*M_PI/180}"/>
      <material name="handslnk_o_color"/>
      <geometry>
        <mesh filename="package://double_arm_tnk_description/meshes/hand_slink_outer_v7.stl"/>
      </geometry>
    </visual>
    <collision>
      <origin rpy="0 0 ${-61.2291*M_PI/180}"/>
      <geometry>
        <mesh filename="package://double_arm_tnk_description/meshes/hand_slink_outer_v7.stl"/>
      </geometry>      
    </collision>
    <inertial>
      <mass value="0.408083E-3" />
      <origin xyz="0.053019776 0.0 0.0" rpy="0 -0 0" />
      <inertia ixx="0.000267073e-5" ixy="6.95893e-15" ixz="0.0" iyy="0.000617382e-5" iyz="0.0" izz="0.000414755e-5" />
    </inertial>
  </link>

  <link name="MANIFNG_U">
    <visual>
      <origin rpy="0 0 ${-6.7682*M_PI/180}"/>
      <material name="manifng_color"/>
      <geometry>
        <mesh filename="package://double_arm_tnk_description/meshes/finger_base_v7.stl"/>
      </geometry>
    </visual>
    <collision>
      <origin rpy="0 0 ${-6.7682*M_PI/180}"/>
      <geometry>
        <mesh filename="package://double_arm_tnk_description/meshes/finger_base_v7.stl"/>
      </geometry>      
    </collision>
    <inertial>
      <mass value="1.32092E-3" />
      <origin xyz="0.0778883 0.0150494 0.0" rpy="0 -0 0" />
      <inertia ixx="0.00159768e-5" ixy="0.000329267e-5" ixz="3.30872e-29" iyy="0.00595697e-5" iyz="1.03398e-30" izz="0.00524922e-5" />
    </inertial>
  </link>

  <link name="HANDTIP_U">
    <visual>
      <origin rpy="0 0 ${6.7682*M_PI/180}"/>
      <material name="handtip_color"/>
      <geometry>
        <mesh filename="package://double_arm_tnk_description/meshes/hand_tip_asm_v7_marge.stl"/>
      </geometry>
    </visual>
    <collision>
      <origin rpy="0 0 ${6.7682*M_PI/180}"/>
      <geometry>
        <mesh filename="package://double_arm_tnk_description/meshes/hand_tip_asm_v7_marge.stl"/>
      </geometry>      
    </collision>
    <inertial>
      <mass value="1.62187E-3" />
      <origin xyz="0.0581795 -0.0268036 0.0" rpy="0 -0 0" />
      <inertia ixx="0.00272616e-5" ixy="0.000478886e-5" ixz="-4.96308e-29" iyy="0.00389972e-5" iyz="1.03398e-29" izz="0.00225372e-5" />
    </inertial>
  </link>

  <link name="HANDLNK_I">
    <visual>
      <origin xyz="0 0 0.0065000000000000335" rpy="0 0 ${6.7682*M_PI/180}"/>
      <material name="handlnk_color"/>
      <geometry>
        <mesh filename="package://double_arm_tnk_description/meshes/handlink_inner_v7.stl"/>
      </geometry>
    </visual>
    <collision>
      <origin xyz="0 0 0.0065000000000000335" rpy="0 0 ${6.7682*M_PI/180}"/>
      <geometry>
        <mesh filename="package://double_arm_tnk_description/meshes/handlink_inner_v7.stl"/>
      </geometry>      
    </collision>
    <inertial>
      <mass value="0.732866E-3" />
      <origin xyz="0.0921655 -0.00204929 0.0" rpy="0 -0 0" />
      <inertia ixx="0.000257575e-5" ixy="5.00832e-11" ixz="0.0" iyy="0.00268959e-5" iyz="0.0" izz="0.00253442e-5" />
    </inertial>
  </link>

  <link name="MANIFNG_L">
     <visual>
      <origin rpy="0 0 ${-6.7682*M_PI/180}"/>
      <material name="manifng_color"/>
      <geometry>
        <mesh filename="package://double_arm_tnk_description/meshes/finger_base_v7.stl"/>
      </geometry>
    </visual>
    <collision>
      <origin rpy="0 0 ${-6.7682*M_PI/180}"/>
      <geometry>
        <mesh filename="package://double_arm_tnk_description/meshes/finger_base_v7.stl"/>
      </geometry>      
    </collision>
    <inertial>
      <mass value="1.32092E-3" />
      <origin xyz="0.0778883 0.0150494 0.0" rpy="0 -0 0" />
      <inertia ixx="0.00159768e-5" ixy="0.000329267e-5" ixz="0.0" iyy="0.00595697e-5" iyz="0.0" izz="0.00524922e-5" />
    </inertial>
  </link>
  
  <link name="HANDTIP_L">
    <visual>
      <origin rpy="0 0 ${6.7682*M_PI/180}"/>
      <material name="handtip_color"/>
      <geometry>
        <mesh filename="package://double_arm_tnk_description/meshes/hand_tip_asm_v7_marge.stl"/>
      </geometry>
    </visual>
    <collision>
      <origin rpy="0 0 ${6.7682*M_PI/180}"/>
      <geometry>
        <mesh filename="package://double_arm_tnk_description/meshes/hand_tip_asm_v7_marge.stl"/>
      </geometry>      
    </collision>
    <inertial>
      <mass value="1.62187E-3" />
      <origin xyz="0.0581795 -0.0268036 0.0" rpy="0 -0 0" />
      <inertia ixx="0.00272616e-5" ixy="0.000478886e-5" ixz="0.0" iyy="0.00389972e-5" iyz="0.0" izz="0.00225372e-5" />
    </inertial>
  </link>

  <link name="HANDLNK_O">
     <visual>
      <origin xyz="0 0 0.0065000000000000335" rpy="0 0 ${6.7682*M_PI/180}"/>
      <material name="handlnk_color"/>
      <geometry>
        <mesh filename="package://double_arm_tnk_description/meshes/handlink_inner_v7.stl"/>
      </geometry>
    </visual>
    <collision>
      <origin xyz="0 0 0.0065000000000000335" rpy="0 0 ${6.7682*M_PI/180}"/>
      <geometry>
        <mesh filename="package://double_arm_tnk_description/meshes/handlink_inner_v7.stl"/>
      </geometry>      
    </collision>
    <inertial>
      <mass value="0.871915E-3" />
      <origin xyz="0.0928285 -0.00312308 1.58819e-22" rpy="0 -0 0" />
      <inertia ixx="0.000559832e-5" ixy="-1.99551e-10" ixz="-1.65436e-29" iyy="0.00316998e-5" iyz="3.61892e-30" izz="0.00272764e-5" />
    </inertial>
  </link>

  <!-- Joint -->
  <joint name="UFRAME" type="revolute">
    <origin xyz="0.0 0.0 0.3" rpy="0.0 -0.0 3.14159265359" />
    <axis xyz="0 0 1" />
    <parent link="TFRAME" />
    <child link="UFRAME" />
    <limit lower="-11.9991386075" upper="11.9991386075" effort="12000.0" velocity="573.0" />
  </joint>
  <joint name="MNP_SWING" type="revolute">
    <origin xyz="0.5595 -0.13 0.11800000000000005" rpy="0.0 -0.0 0.0" />
    <axis xyz="0 0 1" />
    <parent link="UFRAME" />
    <child link="MNP_SWING" />
    <limit lower="-1.0471975512" upper="1.0471975512" effort="12000.0" velocity="1146.0" />
  </joint>
  <joint name="MANIBOOM" type="revolute">
    <origin xyz="0.07000000000000028 1.942890293094024e-16 0.1400000000000003" rpy="-1.57079632679 1.57079632679 0.0" />
    <axis xyz="0 0 1" />
    <parent link="MNP_SWING" />
    <child link="MANIBOOM" />
    <limit lower="0.0" upper="2.00712863979" effort="15000.0" velocity="573.0" />
  </joint>
  <joint name="MANIARM" type="revolute">
    <origin xyz="-1.4799999999999995 0.0800000000000003 -4.718447854656915e-16" rpy="0.0 -0.0 3.14159265359" />
    <axis xyz="0 0 1" />
    <parent link="MANIBOOM" />
    <child link="MANIARM" />
    <limit lower="-1.91986217719" upper="0.0" effort="12000.0" velocity="573.0" />
  </joint>
  <joint name="MANIELBOW" type="revolute">
    <origin xyz="-0.5499999999999989 0.27000000000000035 1.942890293094024e-16" rpy="1.57079632679 1.16573417586e-15 1.57079632679" />
    <axis xyz="0 1 0" />
    <parent link="MANIARM" />
    <child link="MANIELBOW" />
    <limit lower="-1.57079632679" upper="0.349065850399" effort="10000.0" velocity="573.0" />
  </joint>
  <joint name="YAWJOINT" type="revolute">
    <origin xyz="-4.440892098500626e-16 5.273559366969494e-16 -0.2300000000000002" rpy="0.0 -0.0 0.0" />
    <axis xyz="1 0 0" />
    <parent link="MANIELBOW" />
    <child link="YAWJOINT" />
    <limit lower="-0.881042206407" upper="0.881042206407" effort="10000.0" velocity="573.0" />
  </joint>
  <joint name="HANDBASE" type="revolute">
    <origin xyz="-4.440892098500626e-16 -2.7755575615628914e-17 -0.40529999999999977" rpy="0.0 -0.0 0.0" />
    <axis xyz="0 0 -1" />
    <parent link="YAWJOINT" />
    <child link="HANDBASE" />
    <limit lower="-4.71238898038" upper="4.71238898038" effort="8000.0" velocity="573.0" />
  </joint>
  <joint name="PUSHROD" type="prismatic">
    <origin xyz="-1.1102230246251565e-16 -2.7755575615628914e-17 -0.0917" rpy="0.0 -0.0 0.0" />
    <axis xyz="0 0 -1" />
    <parent link="HANDBASE" />
    <child link="PUSHROD" />
    <limit lower="-0.000884881930761" upper="0.0" effort="8000.0" velocity="573.0" />
  </joint>
  <joint name="HANDSLNK_I" type="revolute">
    <origin xyz="1.1102230246251565e-16 3.885780586188048e-16 1.1102230246251565e-16" rpy="-1.57079632679 0.502146933762 3.14159265359" />
    <axis xyz="0 0 1" />
    <parent link="PUSHROD" />
    <child link="HANDSLNK_I" />
    <limit lower="-3.00022098418" upper="3.00022098418" effort="100.0" velocity="573.0" />
  </joint>
  <joint name="HANDSLNK_O" type="revolute">
    <origin xyz="1.1102230246251565e-16 3.885780586188048e-16 1.1102230246251565e-16" rpy="1.57079632679 0.502146933762 1.89987128067e-16" />
    <axis xyz="0 0 1" />
    <parent link="PUSHROD" />
    <child link="HANDSLNK_O" />
    <limit lower="-3.00022098418" upper="3.00022098418" effort="100.0" velocity="573.0" />
  </joint>
  <joint name="MANIFNG_U" type="revolute">
    <origin xyz="0.029999999999999916 -2.7755575615628914e-17 -0.1399999999999999" rpy="1.57079632679 1.45266895236 4.23918814852e-15" />
    <axis xyz="0 0 1" />
    <parent link="HANDBASE" />
    <child link="MANIFNG_U" />
    <limit lower="-3.00022098418" upper="3.00022098418" effort="100.0" velocity="573.0" />
  </joint>
  <joint name="HANDTIP_U" type="revolute">
    <origin xyz="0.1710000000000006 -2.220446049250313e-16 -3.885780586188048e-16" rpy="-3.54187949632e-16 -1.17224040023e-16 -0.118127374433" />
    <axis xyz="0 0 1" />
    <parent link="MANIFNG_U" />
    <child link="HANDTIP_U" />
    <limit lower="-3.00022098418" upper="3.00022098418" effort="100.0" velocity="573.0" />
  </joint>
  <joint name="HANDLNK_I" type="revolute">
    <origin xyz="-1.1102230246251565e-16 0.006499999999999978 -0.15499999999999992" rpy="1.57079632679 1.45266895236 4.23918814852e-15" />
    <axis xyz="0 0 1" />
    <parent link="HANDBASE" />
    <child link="HANDLNK_I" />
    <limit lower="-3.00022098418" upper="3.00022098418" effort="100.0" velocity="573.0" />
  </joint>
  <joint name="MANIFNG_L" type="revolute">
    <origin xyz="-0.030000000000000027 0.0 -0.1399999999999999" rpy="1.57079632679 1.45266922743 3.14159265359" />
    <axis xyz="0 0 1" />
    <parent link="HANDBASE" />
    <child link="MANIFNG_L" />
    <limit lower="-3.00022098418" upper="3.00022098418" effort="100.0" velocity="573.0" />
  </joint>
  <joint name="HANDTIP_L" type="revolute">
    <origin xyz="0.17099999999999982 4.440892098500626e-16 3.0531133177191805e-16" rpy="-9.18211105227e-19 9.17549819597e-17 -0.118127374433" />
    <axis xyz="0 0 1" />
    <parent link="MANIFNG_L" />
    <child link="HANDTIP_L" />
    <limit lower="-3.00022098418" upper="3.00022098418" effort="100.0" velocity="573.0" />
  </joint>
  <joint name="HANDLNK_O" type="revolute">
    <origin xyz="-1.1102230246251565e-16 -0.0065000000000000335 -0.15499999999999992" rpy="1.57079632679 1.45266922743 3.14159265359" />
    <axis xyz="0 0 1" />
    <parent link="HANDBASE" />
    <child link="HANDLNK_O" />
    <limit lower="-3.00022098418" upper="3.00022098418" effort="100.0" velocity="573.0" />
  </joint>
  
</robot>
